Workbook

Sheet Read Me
B2: CardioX — EXE Release Verification
B3: Acceptance test workbook for the packaged executable and installer
B5: How to use | C5: Work through the 'EXE Checklist' sheet top to bottom. Set a Result on every row. The Summary sheet totals itself as you go.
B6: Result values | C6: PASS · FAIL · N/A · BLOCKED — pick from the dropdown in the Result column. Cells colour themselves.
B7: Blocking layers | C7: AUT, BLD, INS, LNC, LIC and SEC must be 100% PASS. No exceptions — these are ship-stopping.
B8: Order matters | C8: Later sections assume earlier ones passed. Do not skip ahead.
B9: Before you start | C9: Fill in the Environment sheet, and reset the machine: uninstall CardioX and delete %LOCALAPPDATA%\Deckmount\CardioX.
B10: Failures | C10: Log every FAIL on the Defect Log sheet and put its number in the Defect # column.
B11: Android | C11: The 'Android (KRP)' sheet covers ReportScreen.kt — the Android report screen and PDF export. It is tested separately from the desktop EXE.
B12: Source of truth | C12: Generated from docs/EXE_TEST_CHECKLIST.md and docs/ReportScreen_kt.md. Edit the markdown, then re-run docs/generate_checklist_docs.py.
B14: Sheets
B15: Environment | C15: Machine, build and tester details — fill in first
B16: EXE Checklist | C16: 189 checks across the desktop release
B17: Android (KRP) | C17: 40 checks for ReportScreen.kt
B18: Summary | C18: Live per-layer PASS/FAIL totals and the release verdict
B19: Defect Log | C19: One row per failure
B20: Sign-off | C20: Approval signatures

Sheet Environment
B2: Test environment
B3: A checklist result is meaningless without this.
B5: Field | C5: Value
B6: Build version (src/version.py → APP_VERSION)
B7: Update channel
B8: Installer filename
B9: Installer SHA-256
B10: Build machine OS / Python version
B11: Test machine OS / build
B12: RAM / CPU / logical threads
B13: Environment matrix row (A minimum / B typical / C fresh)
B14: RhythmUltra serial under test
B15: Licence server URL baked into .env
B16: Tester name
B17: Date started
... B21: Environment matrix
B22: A — Minimum | C22: <=8 GB RAM, i3 / <=4 logical threads — triggers is_low_spec_mode()
B23: B — Typical | C23: 16 GB RAM, i5/i7, integrated GPU — the mainstream clinic machine
B24: C — Fresh Windows | C24: No Python, no MSVC redistributables — proves the bundle is complete

Sheet EXE Checklist
A1: CardioX EXE — release verification
A2: Set a Result on every row. Blocking layers must be 100% PASS.
A4: ID | B4: Layer | C4: Blocking | D4: Check | E4: Detail / expected result | F4: Result | G4: Tester | H4: Date | I4: Defect # | J4: Notes
A5: Test environment preparation
A6: PREP-01 | B6: Test environment preparation | D6: Uninstall any existing CardioX (Settings → Apps, or {app}\unins000.exe)
A7: PREP-02 | B7: Test environment preparation | D7: Delete the runtime workspace %LOCALAPPDATA%\Deckmount\CardioX — this is where runtime_dir() in src/utils/app_paths.py stores the | E7: licence token, users.json, ecg_settings.json, reports, logs and the offline queue. Leaving it behind hides first-run bugs.
A8: PREP-03 | B8: Test environment preparation | D8: Confirm %ProgramFiles%\CardioX is gone
A9: PREP-04 | B9: Test environment preparation | D9: Unplug the RhythmUltra device (device-absent paths are tested first)
A10: Automated unit tests
A11: AUT-01 | B11: Automated unit tests | C11: YES | D11: Full suite green | E11: Expected: 180 passed, 7 subtests passed and exit code 0. (Verified on 2026-08-18: 180 passed in 55.33 s.)
A12: AUT-02 | B12: Automated unit tests | C12: YES | D12: python -m pytest tests/test_cardiox_prod.py -q → 76 passed
A13: AUT-03 | B13: Automated unit tests | C13: YES | D13: python -m pytest tests/test_history_and_hyperkalemia.py -q → 104 passed
A14: AUT-04 | B14: Automated unit tests | C14: YES | D14: Suite completes with no display server, no RhythmUltra attached and no network — headless is a hard requirement, because CI has | E14: none of the three.
A15: Build verification
A16: BLD-01 | B16: Build verification | C16: YES | D16: build_release.ps1 regenerates src/version.py with the requested APP_VERSION, UPDATE_CHANNEL and GITHUB_REPOSITORY before | E16: compiling.
A17: BLD-02 | B17: Build verification | C17: YES | D17: PyInstaller stage exits 0 | E17: Any non-zero exit throws "EXE build failed" and must stop the release.
A18: BLD-03 | B18: Build verification | C18: YES | D18: Secret gate holds | E18: _stage_env_for_distribution() in build_exe.py must not print a refusal. Deliberately prove the gate is live: add TEST_SECRET_KEY=abc to .env, rebuild, and confirm the build aborts with "REFUSING TO BUILD — unvetted secret(s) would ship inside the installer". Remove the line and rebuild before continuing.
A19: BLD-04 | B19: Build verification | C19: YES | D19: The staged .env inside dist\CARDIOX\ contains only vetted keys | E19: Diff it against _DIST_ENV_KNOWN_SHIPPED (build_exe.py:115). Any server-side secret present here is a release blocker.
A20: BLD-05 | B20: Build verification | C20: YES | D20: LICENSE_SERVER_URL in the staged .env points at the production gateway, not localhost | E20: Overridable at build time via BUILD_LICENSE_SERVER_URL.
A21: BLD-06 | B21: Build verification | C21: YES | D21: dist\CARDIOX\CARDIOX.exe exists, is --windowed (no console window on launch) and carries the multi-resolution icon from | E21: assets/cardiox_logo.ico.
A22: BLD-07 | B22: Build verification | C22: YES | D22: File properties → Details shows the expected version string
A23: BLD-08 | B23: Build verification | C23: YES | D23: Bundled data present under dist\CARDIOX\_internal\: | E23: assets\, config\ (must contain clinical_config.yaml). Why: without PyYAML + clinical_config.yaml the frozen app silently falls back to Python defaults and every arrhythmia reads "Rhythm Undetermined" — see the comment at build_exe.py:345.
A24: BLD-09 | B24: Build verification | C24: YES | D24: No stale spec used: | E24: the spec is written to build\, not the repo root (--specpath=build). Confirm build\CARDIOX.spec has this run's timestamp.
A25: BLD-10 | B25: Build verification | C25: YES | D25: Excluded frameworks really are absent from _internal: | E25: PyQt6, PySide2, PySide6, notebook, IPython, jinja2.
A26: BLD-11 | B26: Build verification | C26: YES | D26: Inno Setup stage produces dist\installers\Setup_CARDIOX_<version>.exe | E26: A missing ISCC.exe prints "Setup build could not be completed" — install Inno Setup 6 and rerun.
A27: BLD-12 | B27: Build verification | C27: YES | D27: Record the installer SHA-256 in §2
A28: Installer
A29: INS-01 | B29: Installer | C29: YES | D29: Installer requires elevation (PrivilegesRequired=admin) and shows the UAC prompt
A30: INS-02 | B30: Installer | C30: YES | D30: EULA page displays installer/EULA.txt; declining cancels the install cleanly
A31: INS-03 | B31: Installer | C31: YES | D31: Default install directory is {autopf}\CardioX (i.e | E31: C:\Program Files\CardioX).
A32: INS-04 | B32: Installer | C32: YES | D32: The whole dist tree is copied recursively — {app}\_internal\ is present, not just the EXE
A33: INS-05 | B33: Installer | C33: YES | D33: Start Menu group CardioX created with the app entry and Uninstall CardioX
A34: INS-06 | B34: Installer | C34: YES | D34: Desktop icon created only when the "Create a desktop icon" task is ticked
A35: INS-07 | B35: Installer | C35: YES | D35: Both shortcuts show the CardioX logo, not a generic or Python icon, and set WorkingDir to {app}
A36: INS-08 | B36: Installer | C36: YES | D36: The post-install "Launch CardioX" checkbox starts the app successfully
A37: INS-09 | B37: Installer | C37: YES | D37: Silent install Setup_CARDIOX_<v>.exe /VERYSILENT /NORESTART completes and does not auto-launch (skipifsilent)
A38: INS-10 | B38: Installer | C38: YES | D38: Re-running the installer over an existing install upgrades in place without orphaning files in _internal
A39: First launch / cold start
A40: LNC-01 | B40: First launch / cold start | C40: YES | D40: Double-clicking the desktop shortcut on a clean machine (row C) shows the CardioX window | E40: No Python traceback, no missing-DLL dialog, no console flash.
A41: LNC-02 | B41: First launch / cold start | C41: YES | D41: Runtime workspace is created outside Program Files | E41: After first launch, %LOCALAPPDATA%\Deckmount\CardioX exists and contains reports\, logs\, offline_queue\, temp\, src\. Why: _prepare_runtime_workspace() (src/main.py:78) must relocate all writes; writing under Program Files fails for standard users.
...

Sheet Android (KRP)
A1: ReportScreen.kt — Android report screen
A2: Verification for the Android ECG report renderer and PDF export.
A4: ID | B4: Layer | C4: Group | D4: Blocking | E4: Check | F4: Detail / expected result | G4: Result | H4: Tester | I4: Date | J4: Defect # | K4: Notes
A5: Verification checklist
A6: KRP-01 | B6: Verification checklist | C6: Rendering | E6: All three layouts render: | F6: "1x12", "2x6", "3x4".
A7: KRP-02 | B7: Verification checklist | C7: Rendering | E7: An unrecognised layout string falls back to "2x6" rather than crashing
A8: KRP-03 | B8: Verification checklist | C8: Rendering | E8: Grid is 1 mm minor / 5 mm major and spans the full page edge to edge
A9: KRP-04 | B9: Verification checklist | C9: Rendering | E9: Every lane shows its calibration pulse: | F9: 9 mm wide, 10 mm tall.
A10: KRP-05 | B10: Verification checklist | C10: Rendering | E10: Every lane shows its lead label above the trace
A11: KRP-06 | B11: Verification checklist | C11: Rendering | E11: A missing lead key renders an empty lane — label and calibration intact, no crash
A12: KRP-07 | B12: Verification checklist | C12: Rendering | E12: A single-sample lead list renders nothing and does not throw
A13: KRP-08 | B13: Verification checklist | C13: Rendering | E13: The 2×6 rhythm strip uses lead II from leadData5000 and spans the full 10 s
A14: KRP-09 | B14: Verification checklist | C14: Geometry — the checks that need a ruler | E14: Exported PDF printed at 100 % scale: | F14: one large grid box measures 5.0 mm.
A15: KRP-10 | B15: Verification checklist | C15: Geometry — the checks that need a ruler | E15: The calibration pulse measures 10 mm tall and 5 mm across its top segment
A16: KRP-11 | B16: Verification checklist | C16: Geometry — the checks that need a ruler | E16: A 1 mV deflection in the trace measures 10 mm — one large box
A17: KRP-12 | B17: Verification checklist | C17: Geometry — the checks that need a ruler | E17: One second of signal spans 25 mm — five large boxes
A18: KRP-13 | B18: Verification checklist | C18: Geometry — the checks that need a ruler | E18: No strip is clipped: | F18: the last sample of each stream is visible within its lane.
A19: KRP-14 | B19: Verification checklist | C19: Geometry — the checks that need a ruler | E19: Nothing overflows the page in either orientation, including a long organisation name
A20: KRP-15 | B20: Verification checklist | C20: Header and footer | E20: Blank patient fields render as -, not as an empty gap or null
A21: KRP-16 | B21: Verification checklist | C21: Header and footer | E21: The spec line reads 25.0 mm/s 0.5-25 Hz AC:<n>Hz 10.0 mm/mV
A22: KRP-17 | B22: Verification checklist | C22: Header and footer | E22: RV5, SV1 and the index print to 3 decimal places
A23: KRP-18 | B23: Verification checklist | C23: Header and footer | E23: RV5 + SV1 ≥ 3.5 appends *; below the threshold it does not
A24: KRP-19 | B24: Verification checklist | C24: Header and footer | E24: The footer shows the last 4 characters of machineSerial and is horizontally centred
A25: KRP-20 | B25: Verification checklist | C25: Header and footer | E25: hr <= 0 prints exactly "No ECG data available" in the conclusion box and nothing else
A26: KRP-21 | B26: Verification checklist | C26: Header and footer | E26: Blank conclusions and "---" are filtered out
A27: KRP-22 | B27: Verification checklist | C27: Header and footer | E27: Conclusions stay inside the box border in both orientations; numbering is sequential from 1
A28: KRP-23 | B28: Verification checklist | C28: Interaction | E28: The spinner and "Rendering ECG report…" appear, then resolve to the report
A29: KRP-24 | B29: Verification checklist | C29: Interaction | E29: Pinch-zoom clamps at 0.5× and 8×
A30: KRP-25 | B30: Verification checklist | C30: Interaction | E30: Pan moves the report smoothly | F30: (Known issue: pan is unbounded — record the behaviour.)
A31: KRP-26 | B31: Verification checklist | C31: Interaction | E31: Rotating the device re-renders at the new width without crashing
A32: KRP-27 | B32: Verification checklist | C32: Interaction | E32: Back navigation leaves the screen cleanly and cancels any in-flight render
A33: KRP-28 | B33: Verification checklist | C33: Share and download | E33: Share opens the system chooser; the recipient app can open the PDF
A34: KRP-29 | B34: Verification checklist | C34: Share and download | E34: The share spinner shows during generation and both actions disable
A35: KRP-30 | B35: Verification checklist | C35: Share and download | E35: Rapid double-tap on Share starts exactly one operation (mutex)
A36: KRP-31 | B36: Verification checklist | C36: Share and download | E36: Rapid double-tap on Download starts exactly one operation | F36: (Known issue: currently fails — isExporting is never set. See §10.1.)
A37: KRP-32 | B37: Verification checklist | C37: Share and download | E37: Download opens the SAF picker pre-filled with RhythmPro_ECG_<timestamp>.pdf
A38: KRP-33 | B38: Verification checklist | C38: Share and download | E38: Saving writes a valid PDF to the chosen location and toasts success
A39: KRP-34 | B39: Verification checklist | C39: Share and download | E39: Cancelling the picker deletes the temp file and leaves no orphan in cacheDir/shared_pdfs
A40: KRP-35 | B40: Verification checklist | C40: Share and download | E40: The exported PDF opens in Drive, Adobe Reader and Chrome
A41: KRP-36 | B41: Verification checklist | C41: Share and download | E41: Filenames use Gregorian years on a device with a non-Gregorian default locale | F41: (Known issue — see §11.)
...

Sheet Summary
B2: Release summary
B3: Formulas are live — these totals update as the checklist is filled in.
B5: Layer | C5: Blocking | D5: Checks | E5: PASS | F5: FAIL | G5: N/A | H5: Outstanding
B6: Test environment preparation | D6: =COUNTIFS('EXE Checklist'!$B:$B,$B6) | E6: =COUNTIFS('EXE Checklist'!$B:$B,$B6,'EXE Checklist'!$F:$F,"PASS") | F6: =COUNTIFS('EXE Checklist'!$B:$B,$B6,'EXE Checklist'!$F:$F,"FAIL") | G6: =COUNTIFS('EXE Checklist'!$B:$B,$B6,'EXE Checklist'!$F:$F,"N/A") | H6: =D6-E6-F6-G6
B7: Automated unit tests | C7: YES | D7: =COUNTIFS('EXE Checklist'!$B:$B,$B7) | E7: =COUNTIFS('EXE Checklist'!$B:$B,$B7,'EXE Checklist'!$F:$F,"PASS") | F7: =COUNTIFS('EXE Checklist'!$B:$B,$B7,'EXE Checklist'!$F:$F,"FAIL") | G7: =COUNTIFS('EXE Checklist'!$B:$B,$B7,'EXE Checklist'!$F:$F,"N/A") | H7: =D7-E7-F7-G7
B8: Build verification | C8: YES | D8: =COUNTIFS('EXE Checklist'!$B:$B,$B8) | E8: =COUNTIFS('EXE Checklist'!$B:$B,$B8,'EXE Checklist'!$F:$F,"PASS") | F8: =COUNTIFS('EXE Checklist'!$B:$B,$B8,'EXE Checklist'!$F:$F,"FAIL") | G8: =COUNTIFS('EXE Checklist'!$B:$B,$B8,'EXE Checklist'!$F:$F,"N/A") | H8: =D8-E8-F8-G8
B9: Installer | C9: YES | D9: =COUNTIFS('EXE Checklist'!$B:$B,$B9) | E9: =COUNTIFS('EXE Checklist'!$B:$B,$B9,'EXE Checklist'!$F:$F,"PASS") | F9: =COUNTIFS('EXE Checklist'!$B:$B,$B9,'EXE Checklist'!$F:$F,"FAIL") | G9: =COUNTIFS('EXE Checklist'!$B:$B,$B9,'EXE Checklist'!$F:$F,"N/A") | H9: =D9-E9-F9-G9
B10: First launch / cold start | C10: YES | D10: =COUNTIFS('EXE Checklist'!$B:$B,$B10) | E10: =COUNTIFS('EXE Checklist'!$B:$B,$B10,'EXE Checklist'!$F:$F,"PASS") | F10: =COUNTIFS('EXE Checklist'!$B:$B,$B10,'EXE Checklist'!$F:$F,"FAIL") | G10: =COUNTIFS('EXE Checklist'!$B:$B,$B10,'EXE Checklist'!$F:$F,"N/A") | H10: =D10-E10-F10-G10
B11: Licensing & device authorization | C11: YES | D11: =COUNTIFS('EXE Checklist'!$B:$B,$B11) | E11: =COUNTIFS('EXE Checklist'!$B:$B,$B11,'EXE Checklist'!$F:$F,"PASS") | F11: =COUNTIFS('EXE Checklist'!$B:$B,$B11,'EXE Checklist'!$F:$F,"FAIL") | G11: =COUNTIFS('EXE Checklist'!$B:$B,$B11,'EXE Checklist'!$F:$F,"N/A") | H11: =D11-E11-F11-G11
B12: Device / hardware | D12: =COUNTIFS('EXE Checklist'!$B:$B,$B12) | E12: =COUNTIFS('EXE Checklist'!$B:$B,$B12,'EXE Checklist'!$F:$F,"PASS") | F12: =COUNTIFS('EXE Checklist'!$B:$B,$B12,'EXE Checklist'!$F:$F,"FAIL") | G12: =COUNTIFS('EXE Checklist'!$B:$B,$B12,'EXE Checklist'!$F:$F,"N/A") | H12: =D12-E12-F12-G12
B13: 12-Lead ECG module | D13: =COUNTIFS('EXE Checklist'!$B:$B,$B13) | E13: =COUNTIFS('EXE Checklist'!$B:$B,$B13,'EXE Checklist'!$F:$F,"PASS") | F13: =COUNTIFS('EXE Checklist'!$B:$B,$B13,'EXE Checklist'!$F:$F,"FAIL") | G13: =COUNTIFS('EXE Checklist'!$B:$B,$B13,'EXE Checklist'!$F:$F,"N/A") | H13: =D13-E13-F13-G13
B14: HRV module | D14: =COUNTIFS('EXE Checklist'!$B:$B,$B14) | E14: =COUNTIFS('EXE Checklist'!$B:$B,$B14,'EXE Checklist'!$F:$F,"PASS") | F14: =COUNTIFS('EXE Checklist'!$B:$B,$B14,'EXE Checklist'!$F:$F,"FAIL") | G14: =COUNTIFS('EXE Checklist'!$B:$B,$B14,'EXE Checklist'!$F:$F,"N/A") | H14: =D14-E14-F14-G14
B15: Hyperkalemia module | D15: =COUNTIFS('EXE Checklist'!$B:$B,$B15) | E15: =COUNTIFS('EXE Checklist'!$B:$B,$B15,'EXE Checklist'!$F:$F,"PASS") | F15: =COUNTIFS('EXE Checklist'!$B:$B,$B15,'EXE Checklist'!$F:$F,"FAIL") | G15: =COUNTIFS('EXE Checklist'!$B:$B,$B15,'EXE Checklist'!$F:$F,"N/A") | H15: =D15-E15-F15-G15
B16: Reports & PDF | D16: =COUNTIFS('EXE Checklist'!$B:$B,$B16) | E16: =COUNTIFS('EXE Checklist'!$B:$B,$B16,'EXE Checklist'!$F:$F,"PASS") | F16: =COUNTIFS('EXE Checklist'!$B:$B,$B16,'EXE Checklist'!$F:$F,"FAIL") | G16: =COUNTIFS('EXE Checklist'!$B:$B,$B16,'EXE Checklist'!$F:$F,"N/A") | H16: =D16-E16-F16-G16
B17: History | D17: =COUNTIFS('EXE Checklist'!$B:$B,$B17) | E17: =COUNTIFS('EXE Checklist'!$B:$B,$B17,'EXE Checklist'!$F:$F,"PASS") | F17: =COUNTIFS('EXE Checklist'!$B:$B,$B17,'EXE Checklist'!$F:$F,"FAIL") | G17: =COUNTIFS('EXE Checklist'!$B:$B,$B17,'EXE Checklist'!$F:$F,"N/A") | H17: =D17-E17-F17-G17
B18: Cloud sync & offline queue | D18: =COUNTIFS('EXE Checklist'!$B:$B,$B18) | E18: =COUNTIFS('EXE Checklist'!$B:$B,$B18,'EXE Checklist'!$F:$F,"PASS") | F18: =COUNTIFS('EXE Checklist'!$B:$B,$B18,'EXE Checklist'!$F:$F,"FAIL") | G18: =COUNTIFS('EXE Checklist'!$B:$B,$B18,'EXE Checklist'!$F:$F,"N/A") | H18: =D18-E18-F18-G18
B19: Doctor review upload | D19: =COUNTIFS('EXE Checklist'!$B:$B,$B19) | E19: =COUNTIFS('EXE Checklist'!$B:$B,$B19,'EXE Checklist'!$F:$F,"PASS") | F19: =COUNTIFS('EXE Checklist'!$B:$B,$B19,'EXE Checklist'!$F:$F,"FAIL") | G19: =COUNTIFS('EXE Checklist'!$B:$B,$B19,'EXE Checklist'!$F:$F,"N/A") | H19: =D19-E19-F19-G19
B20: Dashboard, settings & auxiliary UI | D20: =COUNTIFS('EXE Checklist'!$B:$B,$B20) | E20: =COUNTIFS('EXE Checklist'!$B:$B,$B20,'EXE Checklist'!$F:$F,"PASS") | F20: =COUNTIFS('EXE Checklist'!$B:$B,$B20,'EXE Checklist'!$F:$F,"FAIL") | G20: =COUNTIFS('EXE Checklist'!$B:$B,$B20,'EXE Checklist'!$F:$F,"N/A") | H20: =D20-E20-F20-G20
B21: Performance on minimum spec | D21: =COUNTIFS('EXE Checklist'!$B:$B,$B21) | E21: =COUNTIFS('EXE Checklist'!$B:$B,$B21,'EXE Checklist'!$F:$F,"PASS") | F21: =COUNTIFS('EXE Checklist'!$B:$B,$B21,'EXE Checklist'!$F:$F,"FAIL") | G21: =COUNTIFS('EXE Checklist'!$B:$B,$B21,'EXE Checklist'!$F:$F,"N/A") | H21: =D21-E21-F21-G21
B22: Security | C22: YES | D22: =COUNTIFS('EXE Checklist'!$B:$B,$B22) | E22: =COUNTIFS('EXE Checklist'!$B:$B,$B22,'EXE Checklist'!$F:$F,"PASS") | F22: =COUNTIFS('EXE Checklist'!$B:$B,$B22,'EXE Checklist'!$F:$F,"FAIL") | G22: =COUNTIFS('EXE Checklist'!$B:$B,$B22,'EXE Checklist'!$F:$F,"N/A") | H22: =D22-E22-F22-G22
B23: Update & uninstall | D23: =COUNTIFS('EXE Checklist'!$B:$B,$B23) | E23: =COUNTIFS('EXE Checklist'!$B:$B,$B23,'EXE Checklist'!$F:$F,"PASS") | F23: =COUNTIFS('EXE Checklist'!$B:$B,$B23,'EXE Checklist'!$F:$F,"FAIL") | G23: =COUNTIFS('EXE Checklist'!$B:$B,$B23,'EXE Checklist'!$F:$F,"N/A") | H23: =D23-E23-F23-G23
B24: Regression checks for the 2026-08-13 fix set | D24: =COUNTIFS('EXE Checklist'!$B:$B,$B24) | E24: =COUNTIFS('EXE Checklist'!$B:$B,$B24,'EXE Checklist'!$F:$F,"PASS") | F24: =COUNTIFS('EXE Checklist'!$B:$B,$B24,'EXE Checklist'!$F:$F,"FAIL") | G24: =COUNTIFS('EXE Checklist'!$B:$B,$B24,'EXE Checklist'!$F:$F,"N/A") | H24: =D24-E24-F24-G24
B25: TOTAL | D25: =SUM(D6:D24) | E25: =SUM(E6:E24) | F25: =SUM(F6:F24) | G25: =SUM(G6:G24) | H25: =SUM(H6:H24)
B27: Blocking layers clear? | D27: =IF((F7+F8+F9+F10+F11+F22)>0,"NO — blocking failures",IF((H7+H8+H9+H10+H11+H22)>0,"NOT YET — checks outstanding","YES"))
B29: Release decision
B30: ☐ | C30: APPROVED — all blocking layers green, remaining defects accepted
B31: ☐ | C31: REJECTED — blocking failures recorded in the Defect Log

Sheet Defect Log
A1: Defect log
A2: Severity — Blocker: ship-stopping · Major: workaround exists · Minor: cosmetic
A4: # | B4: Check ID | C4: Severity | D4: Summary | E4: Steps to reproduce | F4: Raised by | G4: Date | H4: Status
A5: 1
A6: 2
A7: 3
A8: 4
A9: 5
A10: 6
A11: 7
A12: 8
A13: 9
A14: 10
A15: 11
A16: 12
... A44: 40

Sheet Sign-off
B2: Release sign-off
B3: Sign only when the Summary sheet reports blocking layers clear.
B5: Role | C5: Name | D5: Signature | E5: Date
B6: QA Engineer
B7: Engineering Lead
B8: Clinical Reviewer
B9: Release Manager
